[2018-12-07 01:09:22,854] [ERROR] [xinxideMacBook-Pro.local][getdata.py - line:111] 获取activitys异常![Errno 2] No such file or directory: '/Users/xinxi/PycharmProjects/maxauto/report/tmp/allactivity.log'
[2018-12-07 01:09:22,855] [ERROR] [xinxideMacBook-Pro.local][getdata.py - line:146] 计算遍历覆盖率异常!float division by zero
[2018-12-07 01:09:22,909] [ERROR] [xinxideMacBook-Pro.local][getdata.py - line:45] 获取安装耗时数据异常![Errno 2] No such file or directory: '/Users/xinxi/PycharmProjects/maxauto/report/tmp/install_app.log'
[2018-12-07 01:09:22,910] [INFO] [xinxideMacBook-Pro.local][getdata.py - line:60] 获取冷启动数据异常![Errno 2] No such file or directory: '/Users/xinxi/PycharmProjects/maxauto/report/tmp/lanuch_app.log'
[2018-12-07 01:09:22,913] [ERROR] [xinxideMacBook-Pro.local][getdata.py - line:226] 获取崩溃图片异常![Errno 2] No such file or directory: 'images'
[2018-12-07 01:09:22,913] [ERROR] [xinxideMacBook-Pro.local][getdata.py - line:30] 获取登录数据异常![Errno 2] No such file or directory: '/Users/xinxi/PycharmProjects/maxauto/report/tmp/login_app.log'
[2018-12-07 01:10:53,531] [ERROR] [xinxideMacBook-Pro.local][getdata.py - line:226] 获取崩溃图片异常![Errno 2] No such file or directory: 'images'
[2018-12-07 01:12:45,899] [INFO] [xinxideMacBook-Pro.local][server.py - line:32] 启动服务...
[2018-12-07 01:13:04,613] [INFO] [xinxideMacBook-Pro.local][server.py - line:32] 启动服务...
[2018-12-07 01:13:04,629] [INFO] [xinxideMacBook-Pro.local][_internal.py - line:88]  * Running on http://127.0.0.1:3031/ (Press CTRL+C to quit)
[2018-12-07 01:13:04,630] [INFO] [xinxideMacBook-Pro.local][_internal.py - line:88]  * Restarting with stat
[2018-12-07 01:13:04,854] [INFO] [xinxideMacBook-Pro.local][server.py - line:32] 启动服务...
[2018-12-07 01:13:04,860] [WARNING] [xinxideMacBook-Pro.local][_internal.py - line:88]  * Debugger is active!
[2018-12-07 01:13:04,879] [INFO] [xinxideMacBook-Pro.local][_internal.py - line:88]  * Debugger PIN: 120-762-539
[2018-12-07 01:13:36,217] [INFO] [xinxideMacBook-Pro.local][client.py - line:31] 开始获取报告!
[2018-12-07 01:13:36,322] [ERROR] [xinxideMacBook-Pro.local][getdata.py - line:226] 获取崩溃图片异常![Errno 2] No such file or directory: 'images'
[2018-12-07 01:13:36,342] [INFO] [xinxideMacBook-Pro.local][_internal.py - line:88] 127.0.0.1 - - [07/Dec/2018 01:13:36] "POST /getreport HTTP/1.1" 200 -
[2018-12-07 01:13:36,343] [INFO] [xinxideMacBook-Pro.local][client.py - line:36] 服务端状态码:200
[2018-12-07 01:13:36,344] [INFO] [xinxideMacBook-Pro.local][client.py - line:40] 报告路径:/Users/xinxi/PycharmProjects/maxauto/report/reports/report_20181207011336.html
[2018-12-07 01:14:29,526] [INFO] [xinxideMacBook-Pro.local][client.py - line:31] 开始获取报告!
[2018-12-07 01:14:29,638] [ERROR] [xinxideMacBook-Pro.local][getdata.py - line:226] 获取崩溃图片异常![Errno 2] No such file or directory: 'images'
[2018-12-07 01:14:29,640] [INFO] [xinxideMacBook-Pro.local][_internal.py - line:88] 127.0.0.1 - - [07/Dec/2018 01:14:29] "POST /getreport HTTP/1.1" 200 -
[2018-12-07 01:14:29,641] [INFO] [xinxideMacBook-Pro.local][client.py - line:36] 服务端状态码:200
[2018-12-07 01:14:29,641] [INFO] [xinxideMacBook-Pro.local][client.py - line:40] 报告路径:/Users/xinxi/PycharmProjects/maxauto/report/reports/report_20181207011429.html
[2018-12-07 01:14:30,068] [INFO] [xinxideMacBook-Pro.local][_internal.py - line:88]  * Detected change in '/Users/xinxi/PycharmProjects/maxauto/config.py', reloading
[2018-12-07 01:14:30,111] [INFO] [xinxideMacBook-Pro.local][_internal.py - line:88]  * Restarting with stat
[2018-12-07 01:14:30,535] [INFO] [xinxideMacBook-Pro.local][server.py - line:32] 启动服务...
[2018-12-07 01:14:30,551] [WARNING] [xinxideMacBook-Pro.local][_internal.py - line:88]  * Debugger is active!
[2018-12-07 01:14:30,570] [INFO] [xinxideMacBook-Pro.local][_internal.py - line:88]  * Debugger PIN: 120-762-539
[2018-12-07 01:14:50,552] [INFO] [xinxideMacBook-Pro.local][client.py - line:31] 开始获取报告!
[2018-12-07 01:14:50,715] [INFO] [xinxideMacBook-Pro.local][_internal.py - line:88] 127.0.0.1 - - [07/Dec/2018 01:14:50] "POST /getreport HTTP/1.1" 200 -
[2018-12-07 01:14:50,721] [INFO] [xinxideMacBook-Pro.local][client.py - line:36] 服务端状态码:200
[2018-12-07 01:14:50,722] [INFO] [xinxideMacBook-Pro.local][client.py - line:40] 报告路径:/Users/xinxi/PycharmProjects/maxauto/report/reports/report_20181207011450.html
[2018-12-07 12:42:09,289] [ERROR] [bogon][predata.py - line:68] 获取页面数据异常![Errno 2] No such file or directory: '/Users/xinxi/PycharmProjects/maxauto/report/tmp/page.log'
[2018-12-07 12:42:09,319] [ERROR] [bogon][getdata.py - line:128] 获取运行的activity异常![Errno 2] No such file or directory: '/Users/xinxi/PycharmProjects/maxauto/report/tmp/acts.log'
[2018-12-07 12:42:09,319] [ERROR] [bogon][getdata.py - line:111] 获取activitys异常![Errno 2] No such file or directory: '/Users/xinxi/PycharmProjects/maxauto/report/tmp/allactivity.log'
[2018-12-07 12:42:09,319] [ERROR] [bogon][getdata.py - line:146] 计算遍历覆盖率异常!float division by zero
[2018-12-07 12:42:09,380] [ERROR] [bogon][getdata.py - line:45] 获取安装耗时数据异常![Errno 2] No such file or directory: '/Users/xinxi/PycharmProjects/maxauto/report/tmp/install_app.log'
[2018-12-07 12:42:09,380] [INFO] [bogon][getdata.py - line:60] 获取冷启动数据异常![Errno 2] No such file or directory: '/Users/xinxi/PycharmProjects/maxauto/report/tmp/lanuch_app.log'
[2018-12-07 12:42:09,381] [ERROR] [bogon][getdata.py - line:93] 获取crash次数异常![Errno 2] No such file or directory: '/Users/xinxi/PycharmProjects/maxauto/report/tmp/crash.log'
[2018-12-07 12:42:09,381] [ERROR] [bogon][getdata.py - line:170] 获取遍历的页面列表异常![Errno 2] No such file or directory: '/Users/xinxi/PycharmProjects/maxauto/report/tmp/acts.log'
[2018-12-07 12:42:09,382] [ERROR] [bogon][getdata.py - line:226] 获取崩溃图片异常![Errno 2] No such file or directory: '/Users/xinxi/PycharmProjects/maxauto/monkey/images'
[2018-12-07 12:42:09,382] [ERROR] [bogon][getdata.py - line:30] 获取登录数据异常![Errno 2] No such file or directory: '/Users/xinxi/PycharmProjects/maxauto/report/tmp/login_app.log'
[2018-12-07 12:42:52,748] [ERROR] [bogon][app.py - line:1761] Exception on /getreport [POST]
Traceback (most recent call last):
  File "/usr/local/lib/python2.7/site-packages/flask/app.py", line 2292, in wsgi_app
    response = self.full_dispatch_request()
  File "/usr/local/lib/python2.7/site-packages/flask/app.py", line 1815, in full_dispatch_request
    rv = self.handle_user_exception(e)
  File "/usr/local/lib/python2.7/site-packages/flask/app.py", line 1718, in handle_user_exception
    reraise(exc_type, exc_value, tb)
  File "/usr/local/lib/python2.7/site-packages/flask/app.py", line 1813, in full_dispatch_request
    rv = self.dispatch_request()
  File "/usr/local/lib/python2.7/site-packages/flask/app.py", line 1799, in dispatch_request
    return self.view_functions[rule.endpoint](**req.view_args)
  File "/Users/xinxi/PycharmProjects/maxauto/report/server.py", line 55, in html
    data = read_mem()
  File "/Users/xinxi/PycharmProjects/maxauto/report/predata.py", line 41, in read_mem
    with open(mem_path, 'r') as f:
IOError: [Errno 2] No such file or directory: '/Users/xinxi/PycharmProjects/maxauto/report/tmp/mem.log'
[2018-12-07 13:25:30,981] [ERROR] [bogon][app.py - line:1761] Exception on /getreport [POST]
Traceback (most recent call last):
  File "/usr/local/lib/python2.7/site-packages/flask/app.py", line 2292, in wsgi_app
    response = self.full_dispatch_request()
  File "/usr/local/lib/python2.7/site-packages/flask/app.py", line 1815, in full_dispatch_request
    rv = self.handle_user_exception(e)
  File "/usr/local/lib/python2.7/site-packages/flask/app.py", line 1718, in handle_user_exception
    reraise(exc_type, exc_value, tb)
  File "/usr/local/lib/python2.7/site-packages/flask/app.py", line 1813, in full_dispatch_request
    rv = self.dispatch_request()
  File "/usr/local/lib/python2.7/site-packages/flask/app.py", line 1799, in dispatch_request
    return self.view_functions[rule.endpoint](**req.view_args)
  File "/Users/xinxi/PycharmProjects/maxauto/report/server.py", line 55, in html
    data = read_mem()
  File "/Users/xinxi/PycharmProjects/maxauto/report/predata.py", line 41, in read_mem
    with open(mem_path, 'r') as f:
IOError: [Errno 2] No such file or directory: '/Users/xinxi/PycharmProjects/maxauto/report/tmp/mem.log'
[2018-12-07 14:22:57,965] [ERROR] [bogon][app.py - line:1761] Exception on /getreport [POST]
Traceback (most recent call last):
  File "/usr/local/lib/python2.7/site-packages/flask/app.py", line 2292, in wsgi_app
    response = self.full_dispatch_request()
  File "/usr/local/lib/python2.7/site-packages/flask/app.py", line 1815, in full_dispatch_request
    rv = self.handle_user_exception(e)
  File "/usr/local/lib/python2.7/site-packages/flask/app.py", line 1718, in handle_user_exception
    reraise(exc_type, exc_value, tb)
  File "/usr/local/lib/python2.7/site-packages/flask/app.py", line 1813, in full_dispatch_request
    rv = self.dispatch_request()
  File "/usr/local/lib/python2.7/site-packages/flask/app.py", line 1799, in dispatch_request
    return self.view_functions[rule.endpoint](**req.view_args)
  File "/Users/xinxi/PycharmProjects/maxauto/report/server.py", line 55, in html
    data = read_mem()
  File "/Users/xinxi/PycharmProjects/maxauto/report/predata.py", line 41, in read_mem
    with open(mem_path, 'r') as f:
IOError: [Errno 2] No such file or directory: '/Users/xinxi/PycharmProjects/maxauto/report/tmp/mem.log'
[2018-12-07 14:23:16,501] [ERROR] [bogon][app.py - line:1761] Exception on /getreport [POST]
Traceback (most recent call last):
  File "/usr/local/lib/python2.7/site-packages/flask/app.py", line 2292, in wsgi_app
    response = self.full_dispatch_request()
  File "/usr/local/lib/python2.7/site-packages/flask/app.py", line 1815, in full_dispatch_request
    rv = self.handle_user_exception(e)
  File "/usr/local/lib/python2.7/site-packages/flask/app.py", line 1718, in handle_user_exception
    reraise(exc_type, exc_value, tb)
  File "/usr/local/lib/python2.7/site-packages/flask/app.py", line 1813, in full_dispatch_request
    rv = self.dispatch_request()
  File "/usr/local/lib/python2.7/site-packages/flask/app.py", line 1799, in dispatch_request
    return self.view_functions[rule.endpoint](**req.view_args)
  File "/Users/xinxi/PycharmProjects/maxauto/report/server.py", line 69, in html
    data1 = read_cpu()
  File "/Users/xinxi/PycharmProjects/maxauto/report/predata.py", line 25, in read_cpu
    with open(cpu_path, 'r') as f:
IOError: [Errno 2] No such file or directory: '/Users/xinxi/PycharmProjects/maxauto/report/tmp/cpu.log'
[2018-12-07 14:23:40,993] [ERROR] [bogon][app.py - line:1761] Exception on /getreport [POST]
Traceback (most recent call last):
  File "/usr/local/lib/python2.7/site-packages/flask/app.py", line 2292, in wsgi_app
    response = self.full_dispatch_request()
  File "/usr/local/lib/python2.7/site-packages/flask/app.py", line 1815, in full_dispatch_request
    rv = self.handle_user_exception(e)
  File "/usr/local/lib/python2.7/site-packages/flask/app.py", line 1718, in handle_user_exception
    reraise(exc_type, exc_value, tb)
  File "/usr/local/lib/python2.7/site-packages/flask/app.py", line 1813, in full_dispatch_request
    rv = self.dispatch_request()
  File "/usr/local/lib/python2.7/site-packages/flask/app.py", line 1799, in dispatch_request
    return self.view_functions[rule.endpoint](**req.view_args)
  File "/Users/xinxi/PycharmProjects/maxauto/report/server.py", line 69, in html
    data1 = read_cpu()
  File "/Users/xinxi/PycharmProjects/maxauto/report/predata.py", line 25, in read_cpu
    with open(cpu_path, 'r') as f:
IOError: [Errno 2] No such file or directory: '/Users/xinxi/PycharmProjects/maxauto/report/tmp/cpu.log'
[2018-12-07 14:28:06,150] [ERROR] [bogon][getdata.py - line:111] 获取activitys异常![Errno 2] No such file or directory: '/Users/xinxi/PycharmProjects/maxauto/report/tmp/allactivity.log'
[2018-12-07 14:28:06,151] [ERROR] [bogon][getdata.py - line:146] 计算遍历覆盖率异常!float division by zero
[2018-12-07 14:28:06,471] [ERROR] [bogon][getdata.py - line:45] 获取安装耗时数据异常![Errno 2] No such file or directory: '/Users/xinxi/PycharmProjects/maxauto/report/tmp/install_app.log'
[2018-12-07 14:28:06,471] [INFO] [bogon][getdata.py - line:60] 获取冷启动数据异常![Errno 2] No such file or directory: '/Users/xinxi/PycharmProjects/maxauto/report/tmp/lanuch_app.log'
[2018-12-07 14:28:06,471] [ERROR] [bogon][getdata.py - line:93] 获取crash次数异常![Errno 2] No such file or directory: '/Users/xinxi/PycharmProjects/maxauto/report/tmp/crash.log'
[2018-12-07 14:28:06,480] [ERROR] [bogon][getdata.py - line:226] 获取崩溃图片异常![Errno 2] No such file or directory: '/Users/xinxi/PycharmProjects/maxauto/monkey/images'
[2018-12-07 14:28:06,482] [ERROR] [bogon][getdata.py - line:30] 获取登录数据异常![Errno 2] No such file or directory: '/Users/xinxi/PycharmProjects/maxauto/report/tmp/login_app.log'
